<?xml version="1.0"?>
<robot name="army_differential_drive_robot">

  <link name="base_link">
    <inertial>
      <origin xyz="0 0 0.1" rpy="0 0 0"/>
      <mass value="1.0"/>
      <inertia ixx="0.1" ixy="0.0" ixz="0.0" iyy="0.1" iyz="0.0" izz="0.1"/>
    </inertial>
    <visual>
      <origin xyz="0 0 0" rpy="0 0 0"/>
      <geometry>
        <box size="0.5 0.5 0.2"/> <!-- Make the base a bit bigger -->
      </geometry>
      <material name="army_green">
        <color rgba="0.2 0.5 0.2 1"/> <!-- Army green color -->
      </material>
    </visual>
    <collision>
      <origin xyz="0 0 0" rpy="0 0 0"/>
      <geometry>
        <box size="0.5 0.5 0.2"/>
      </geometry>
    </collision>
  </link>

  <link name="left_wheel">
    <inertial>
      <origin xyz="0 0 0" rpy="0 0 0"/>
      <mass value="0.5"/>
      <inertia ixx="0.1" ixy="0.0" ixz="0.0" iyy="0.1" iyz="0.0" izz="0.1"/>
    </inertial>
    <visual>
      <origin xyz="0 0 0" rpy="1.5708 0 0"/>
      <geometry>
        <cylinder radius="0.06" length="0.03"/> <!-- Slightly bigger wheels -->
      </geometry>
      <material name="dark_black">
        <color rgba="0.1 0.1 0.1 1"/> <!-- Darker black color -->
      </material>
    </visual>
    <collision>
      <origin xyz="0 0 0" rpy="1.5708 0 0"/>
      <geometry>
        <cylinder radius="0.06" length="0.03"/>
      </geometry>
    </collision>
  </link>

  <link name="right_wheel">
    <inertial>
      <origin xyz="0 0 0" rpy="0 0 0"/>
      <mass value="0.5"/>
      <inertia ixx="0.1" ixy="0.0" ixz="0.0" iyy="0.1" iyz="0.0" izz="0.1"/>
    </inertial>
    <visual>
      <origin xyz="0 0 0" rpy="1.5708 0 0"/>
      <geometry>
        <cylinder radius="0.06" length="0.03"/>
      </geometry>
      <material name="dark_black">
        <color rgba="0.1 0.1 0.1 1"/>
      </material>
    </visual>
    <collision>
      <origin xyz="0 0 0" rpy="1.5708 0 0"/>
      <geometry>
        <cylinder radius="0.06" length="0.03"/>
      </geometry>
    </collision>
  </link>

  <link name="front_wheel">
    <inertial>
      <origin xyz="0 0 0" rpy="0 0 0"/>
      <mass value="0.5"/>
      <inertia ixx="0.1" ixy="0.0" ixz="0.0" iyy="0.1" iyz="0.0" izz="0.1"/>
    </inertial>
    <visual>
      <origin xyz="0 0 0" rpy="1.5708 0 0"/>
      <geometry>
        <cylinder radius="0.06" length="0.03"/>
      </geometry>
      <material name="dark_black">
        <color rgba="0.1 0.1 0.1 1"/>
      </material>
    </visual>
    <collision>
      <origin xyz="0 0 0" rpy="1.5708 0 0"/>
      <geometry>
        <cylinder radius="0.06" length="0.03"/>
      </geometry>
    </collision>
  </link>

  <link name="back_wheel">
    <inertial>
      <origin xyz="0 0 0" rpy="0 0 0"/>
      <mass value="0.5"/>
      <inertia ixx="0.1" ixy="0.0" ixz="0.0" iyy="0.1" iyz="0.0" izz="0.1"/>
    </inertial>
    <visual>
      <origin xyz="0 0 0" rpy="1.5708 0 0"/>
      <geometry>
        <cylinder radius="0.06" length="0.03"/>
      </geometry>
      <material name="dark_black">
        <color rgba="0.1 0.1 0.1 1"/>
      </material>
    </visual>
    <collision>
      <origin xyz="0 0 0" rpy="1.5708 0 0"/>
      <geometry>
        <cylinder radius="0.06" length="0.03"/>
      </geometry>
    </collision>
  </link>

  <joint name="left_wheel_joint" type="continuous">
    <parent link="base_link"/>
    <child link="left_wheel"/>
    <origin xyz="0 0.25 -0.1" rpy="0 0 0"/> <!-- Adjusted position -->
    <axis xyz="0 1 0"/>
  </joint>

  <joint name="right_wheel_joint" type="continuous">
    <parent link="base_link"/>
    <child link="right_wheel"/>
    <origin xyz="0 -0.25 -0.1" rpy="0 0 0"/> <!-- Adjusted position -->
    <axis xyz="0 1 0"/>
  </joint>

  <joint name="front_wheel_joint" type="continuous">
    <parent link="base_link"/>
    <child link="front_wheel"/>
    <origin xyz="0.25 0 -0.1" rpy="0 0 0"/> <!-- Adjusted position -->
    <axis xyz="0 1 0"/>
  </joint>

  <joint name="back_wheel_joint" type="continuous">
    <parent link="base_link"/>
    <child link="back_wheel"/>
    <origin xyz="-0.25 0 -0.1" rpy="0 0 0"/> <!-- Adjusted position -->
    <axis xyz="0 1 0"/>
  </joint>

  <gazebo>
    <plugin name="robot_state_publisher" filename="libgazebo_ros_robot_state.so">
      <robotNamespace>/</robotNamespace>
    </plugin>

    <plugin name="joint_state_publisher" filename="libgazebo_ros_joint_state_publisher.so">
      <joint_state_topic>joint_states</joint_state_topic>
      <robotNamespace>/</robotNamespace>
    </plugin>

    <plugin name="differential_drive_controller" filename="libgazebo_ros_diff_drive.so">
      <robotNamespace>/</robotNamespace>
      <leftJoint>left_wheel_joint</leftJoint>
      <rightJoint>right_wheel_joint</rightJoint>
      <wheelSeparation>0.5</wheelSeparation>
      <wheelRadius>0.06</wheelRadius>
      <publishWheelTF>true</publishWheelTF>
      <publishWheelJointState>true</publishWheelJointState>
      <publishTf>true</publishTf>
      <updateRate>50</updateRate>
      <commandTopic>cmd_vel</commandTopic>
      <odometryTopic>odom</odometryTopic>
      <odometryFrame>odom</odometryFrame>
      <robotBaseFrame>base_link</robotBaseFrame>
      <odometrySource>1</odometrySource>
      <wheelDiameter>0.12</wheelDiameter>
      <wheelAcceleration>0</wheelAcceleration>
      <wheelTorque>5</wheelTorque>
    </plugin>
  </gazebo>

  <link name="laser">
    <inertial>
      <mass value="1e-5" />
      <inertia ixx="1e-6" ixy="0.0" ixz="0.0" iyy="1e-6" iyz="0.0" izz="1e-6" />
    </inertial>
    <visual>
      <origin xyz="0 0 0" rpy="0 0 0" />
      <geometry>
        <box size="0.15 0.15 0.15" /> <!-- Slightly larger laser -->
      </geometry>
      <material name="camouflage">
        <color rgba="0.4 0.4 0.3 1"/> <!-- Camouflage color -->
      </material>
    </visual>
    <collision>
      <origin xyz="0 0 0" rpy="0 0 0" />
      <geometry>
        <box size="0.15 0.15 0.15" />
      </geometry>
    </collision>
  </link>

  <joint name="laser_joint" type="fixed">
    <parent link="base_link" />
    <child link="laser" />
    <origin xyz="0.2 0 0.2" rpy="0 0 0" /> <!-- Adjusted position -->
  </joint>

  <gazebo reference="laser">
    <sensor type="ray" name="laser_sensor">
      <pose>0 0 0 0 0 0</pose>
      <visualize>true</visualize>
      <update_rate>40</update_rate>
      <ray>
        <scan>
          <horizontal>
            <samples>640</samples>
            <resolution>1</resolution>
            <min_angle>-1.5708</min_angle>
            <max_angle>1.5708</max_angle>
          </horizontal>
        </scan>
        <range>
          <min>0.1</min>
          <max>10.0</max>
          <resolution>0.01</resolution>
        </range>
      </ray>
      <plugin name="gazebo_ros_laser" filename="libgazebo_ros_laser.so">
        <topicName>scan</topicName>
        <frameName>laser</frameName>
      </plugin>
    </sensor>
  </gazebo>

</robot>
